# Converted from schematic
# THIS TEMPLATE USES DEFAULTS!  Please edit for corrections.
# If you need help, consult template_rules.txt

weight=4
embed_into_distance=10
dimensions=11,13,13
allowable_overhang=8
max_cut_in=0
cut_in_buffer=0
max_leveling=0
leveling_buffer=0
preserve_water=0
preserve_lava=0
preserve_plants=0


rule1=0,100,1
rule2=0,100,15
rule3=0,100,98-1
rule4=0,100,98-2
rule5=0,100,98
rule6=0,100,109
rule7=0,100,11
rule8=0,100,109-1
rule9=0,100,44-5
rule10=0,100,109-3
rule11=0,100,43
rule12=0,100,65-3
rule13=0,100,26
rule14=0,100,26-8
rule15=0,100,26-3
rule16=0,100,26-11
rule17=0,100,61-3
rule18=0,100,101
rule19=0,100,50-2
rule20=0,100,50-4
rule21=0,100,50-3
rule22=0,100,98-3
rule23=0,0,35-5
rule24=0,100,96-2


layer
1,1,1,1,1,1,1,1,1,1,1,1,1
1,1,1,1,1,1,1,1,1,1,1,1,1
1,1,1,1,1,1,1,1,1,1,1,1,1
1,1,1,1,1,1,1,1,1,1,1,1,1
1,1,1,2,2,1,1,1,1,1,1,1,1
1,1,1,2,2,1,1,1,1,1,1,1,1
1,1,1,1,1,1,1,1,1,1,1,1,1
1,1,1,1,1,1,1,1,1,1,1,1,1
1,1,1,1,1,1,1,1,1,1,1,1,1
1,1,1,1,1,1,1,1,1,1,1,1,1
1,1,1,1,1,1,1,1,1,1,1,1,1
1,1,1,1,1,1,1,1,1,1,1,1,1
1,1,1,1,1,1,1,1,1,1,1,1,1
endlayer

layer
1,1,1,1,1,1,1,1,1,1,1,1,1
1,4,5,5,5,4,4,5,4,4,4,3,1
1,5,5,5,4,5,5,4,5,4,3,4,1
1,3,5,5,5,5,5,5,3,5,5,5,1
1,5,5,3,5,5,5,5,5,5,5,5,1
1,5,5,5,5,5,5,5,5,5,3,5,1
1,5,5,4,5,3,5,5,5,5,4,5,1
1,3,4,5,4,5,4,5,5,4,5,4,1
1,5,5,5,5,4,5,5,5,4,5,4,1
1,4,5,5,5,4,4,4,5,5,3,5,1
1,5,5,5,5,4,5,5,4,5,5,4,1
1,5,3,5,5,5,4,5,4,4,5,5,1
1,1,1,1,1,1,1,1,1,1,1,1,1
endlayer

layer
1,1,1,1,1,1,1,1,1,1,1,1,1
1,3,3,4,3,0,0,3,5,5,5,5,1
1,5,14,13,3,0,0,5,0,0,0,4,1
1,4,0,0,0,0,12,5,0,0,0,5,1
1,3,5,3,4,0,0,0,4,0,5,4,1
1,0,0,0,0,0,0,0,0,0,0,0,1
1,0,0,0,0,0,0,0,0,0,0,0,1
1,4,4,0,5,0,0,0,3,5,5,5,1
1,4,0,0,4,0,0,0,0,9,6,4,1
1,5,15,0,5,0,0,11,0,10,7,5,1
1,5,16,0,4,0,0,0,0,9,8,5,1
1,5,5,5,3,0,0,5,4,5,4,5,1
1,1,1,1,1,1,1,1,1,1,1,1,1
endlayer

layer
1,1,1,1,1,1,1,1,1,1,1,1,1
1,5,5,5,5,0,0,4,5,3,4,5,1
1,5,20,0,5,0,0,5,0,0,0,5,1
1,5,0,0,0,0,12,3,0,0,0,5,1
1,4,5,4,5,0,0,0,5,0,4,5,1
1,0,0,0,0,0,0,0,0,0,0,0,1
1,0,0,0,0,0,0,0,0,0,0,0,1
1,5,5,0,5,0,0,0,18,18,18,5,1
1,5,0,0,5,0,0,0,0,0,0,17,1
1,5,0,0,5,0,0,0,0,0,0,4,1
1,4,0,19,4,0,0,0,0,0,0,17,1
1,5,5,4,3,0,0,5,4,5,5,5,1
1,1,1,1,1,1,1,1,1,1,1,1,1
endlayer

layer
1,1,1,1,1,1,1,1,1,1,1,1,1
1,5,4,4,5,5,5,5,5,5,5,3,1
1,3,5,5,5,5,4,5,0,0,21,4,1
1,5,4,4,22,0,12,4,0,0,0,5,1
1,3,5,5,5,0,0,5,5,22,4,5,1
1,5,4,0,0,0,0,0,0,0,5,5,1
1,4,5,0,0,0,0,0,0,0,4,4,1
1,5,5,22,4,0,0,0,5,5,4,4,1
1,4,5,5,4,0,0,0,0,0,0,5,1
1,5,4,3,5,0,0,0,0,0,0,5,1
1,5,5,5,3,4,5,4,4,4,5,4,1
1,5,5,5,5,5,5,5,5,5,5,5,1
1,1,1,1,1,1,1,1,1,1,1,1,1
endlayer

layer
1,1,1,1,1,1,1,1,1,1,1,1,1
1,1,1,1,1,1,1,1,1,1,1,1,1
1,1,1,1,1,1,1,1,1,1,1,1,1
1,1,1,1,1,1,12,1,1,1,1,1,1
1,1,1,1,1,1,1,1,1,1,1,1,1
1,1,1,1,1,1,1,1,1,1,1,1,1
1,1,1,1,1,1,1,1,1,1,1,1,1
1,1,1,1,1,1,1,1,1,1,1,1,1
1,1,1,1,1,1,1,1,1,1,1,1,1
1,1,1,1,1,1,1,1,1,1,1,1,1
1,1,1,1,1,1,1,1,1,1,1,1,1
1,1,1,1,1,1,1,1,1,1,1,1,1
1,1,1,1,1,1,1,1,1,1,1,1,1
endlayer

layer
23,23,23,23,23,23,23,23,23,23,23,23,23
23,23,23,23,23,23,23,23,23,23,23,23,23
23,23,23,23,23,1,1,1,23,23,23,23,23
23,23,23,23,23,1,12,1,23,23,23,23,23
23,23,23,23,23,1,1,1,23,23,23,23,23
23,23,23,23,23,23,23,23,23,23,23,23,23
23,23,23,23,23,23,23,23,23,23,23,23,23
23,23,23,23,23,23,23,23,23,23,23,23,23
23,23,23,23,23,23,23,23,23,23,23,23,23
23,23,23,23,23,23,23,23,23,23,23,23,23
23,23,23,23,23,23,23,23,23,23,23,23,23
23,23,23,23,23,23,23,23,23,23,23,23,23
23,23,23,23,23,23,23,23,23,23,23,23,23
endlayer

layer
23,23,23,23,23,23,23,23,23,23,23,23,23
23,23,23,23,23,23,23,23,23,23,23,23,23
23,23,23,23,23,1,1,1,23,23,23,23,23
23,23,23,23,23,1,12,1,23,23,23,23,23
23,23,23,23,23,1,1,1,23,23,23,23,23
23,23,23,23,23,23,23,23,23,23,23,23,23
23,23,23,23,23,23,23,23,23,23,23,23,23
23,23,23,23,23,23,23,23,23,23,23,23,23
23,23,23,23,23,23,23,23,23,23,23,23,23
23,23,23,23,23,23,23,23,23,23,23,23,23
23,23,23,23,23,23,23,23,23,23,23,23,23
23,23,23,23,23,23,23,23,23,23,23,23,23
23,23,23,23,23,23,23,23,23,23,23,23,23
endlayer

layer
23,23,23,23,23,23,23,23,23,23,23,23,23
23,23,23,23,23,23,23,23,23,23,23,23,23
23,23,23,23,23,1,1,1,23,23,23,23,23
23,23,23,23,23,1,12,1,23,23,23,23,23
23,23,23,23,23,1,1,1,23,23,23,23,23
23,23,23,23,23,23,23,23,23,23,23,23,23
23,23,23,23,23,23,23,23,23,23,23,23,23
23,23,23,23,23,23,23,23,23,23,23,23,23
23,23,23,23,23,23,23,23,23,23,23,23,23
23,23,23,23,23,23,23,23,23,23,23,23,23
23,23,23,23,23,23,23,23,23,23,23,23,23
23,23,23,23,23,23,23,23,23,23,23,23,23
23,23,23,23,23,23,23,23,23,23,23,23,23
endlayer

layer
23,23,23,23,23,23,23,23,23,23,23,23,23
23,23,23,23,23,23,23,23,23,23,23,23,23
23,23,23,23,23,1,1,1,23,23,23,23,23
23,23,23,23,23,1,12,1,23,23,23,23,23
23,23,23,23,23,1,1,1,23,23,23,23,23
23,23,23,23,23,23,23,23,23,23,23,23,23
23,23,23,23,23,23,23,23,23,23,23,23,23
23,23,23,23,23,23,23,23,23,23,23,23,23
23,23,23,23,23,23,23,23,23,23,23,23,23
23,23,23,23,23,23,23,23,23,23,23,23,23
23,23,23,23,23,23,23,23,23,23,23,23,23
23,23,23,23,23,23,23,23,23,23,23,23,23
23,23,23,23,23,23,23,23,23,23,23,23,23
endlayer

layer
0,0,0,0,0,0,0,0,0,0,0,0,0
0,0,0,0,0,0,0,0,0,0,0,0,0
0,0,0,0,0,9,9,9,0,0,0,0,0
0,0,0,0,0,9,24,9,0,0,0,0,0
0,0,0,0,0,9,9,9,0,0,0,0,0
0,0,0,0,0,0,0,0,0,0,0,0,0
0,0,0,0,0,0,0,0,0,0,0,0,0
0,0,0,0,0,0,0,0,0,0,0,0,0
0,0,0,0,0,0,0,0,0,0,0,0,0
0,0,0,0,0,0,0,0,0,0,0,0,0
0,0,0,0,0,0,0,0,0,0,0,0,0
0,0,0,0,0,0,0,0,0,0,0,0,0
0,0,0,0,0,0,0,0,0,0,0,0,0
endlayer

