# Converted from schematic
# THIS TEMPLATE USES DEFAULTS!  Please edit for corrections.
# If you need help, consult template_rules.txt

weight=1
embed_into_distance=1
acceptable_target_blocks=1,2,3,12,13
dimensions=8,9,10
allowable_overhang=0
max_cut_in=2
cut_in_buffer=1
max_leveling=2
leveling_buffer=1
preserve_water=0
preserve_lava=0
preserve_plants=0


rule1=0,100,24
rule2=0,100,12
rule3=0,100,44-1
rule4=0,100,64
rule5=0,100,101
rule6=0,100,50-3
rule7=0,100,64-8
rule8=0,100,44-10
rule9=0,100,64-1
rule10=0,100,50-4


layer
1,1,1,1,1,1,1,1,1,1
1,1,1,1,1,1,1,1,1,1
1,1,1,1,1,1,1,1,1,1
1,1,1,1,1,1,1,1,1,1
1,1,1,1,1,1,1,1,1,1
1,1,1,1,1,1,1,1,1,1
1,1,1,1,1,1,1,1,1,1
1,1,1,1,1,1,1,1,1,1
1,1,1,1,1,2,2,2,2,2
endlayer

layer
1,1,1,4,1,1,1,3,3,1
1,0,0,0,0,0,1,1,1,1
1,0,0,0,0,0,1,1,1,1
1,0,0,0,0,0,1,1,1,1
1,0,0,0,0,0,0,0,0,1
1,0,0,0,0,0,0,0,0,1
1,0,0,0,0,0,0,0,0,1
1,0,0,0,0,0,0,0,0,1
1,1,1,1,1,1,1,1,1,1
endlayer

layer
1,5,1,7,1,1,1,0,0,1
1,0,0,0,0,0,1,0,0,1
5,0,0,0,0,0,1,3,3,1
1,0,0,0,0,0,1,1,1,1
1,0,0,0,0,0,0,0,6,1
1,0,0,0,0,0,0,0,0,5
5,0,0,0,0,0,0,0,0,1
1,0,0,0,0,0,0,0,0,1
1,1,5,1,1,1,1,1,1,1
endlayer

layer
1,1,1,1,1,1,1,0,0,1
1,8,8,8,8,1,1,0,0,1
1,8,8,8,8,1,1,0,0,1
1,8,8,8,8,1,1,0,0,1
1,8,8,8,1,1,1,3,3,1
1,8,8,8,1,1,1,1,1,1
1,8,8,8,1,1,1,1,1,1
1,8,8,8,1,1,1,1,1,1
1,1,1,1,1,1,1,1,1,1
endlayer

layer
1,1,1,1,1,1,1,0,0,1
1,0,0,0,1,0,0,0,0,1
1,0,0,0,1,0,0,0,0,1
1,0,0,0,1,0,0,0,0,1
1,0,0,0,9,0,0,0,0,1
1,0,0,0,1,0,0,0,0,1
1,0,0,0,1,0,0,0,0,1
1,0,0,0,1,0,0,0,0,1
1,1,1,1,1,1,1,1,1,1
endlayer

layer
1,1,1,1,1,0,0,0,0,0
1,0,0,0,1,0,0,0,0,0
5,0,0,0,5,0,0,0,0,0
1,10,0,6,1,0,0,0,0,0
1,0,0,0,7,0,0,0,0,0
1,10,0,6,1,0,0,0,0,0
5,0,0,0,5,0,0,0,0,0
1,0,0,0,1,0,0,0,0,0
1,1,1,1,1,0,0,0,0,0
endlayer

layer
1,1,1,1,1,0,0,0,0,0
1,8,8,8,1,0,0,0,0,0
1,8,8,8,1,0,0,0,0,0
1,8,8,8,1,0,0,0,0,0
1,8,8,8,1,0,0,0,0,0
1,8,8,8,1,0,0,0,0,0
1,8,8,8,1,0,0,0,0,0
1,8,8,8,1,0,0,0,0,0
1,1,1,1,1,0,0,0,0,0
endlayer

layer
3,3,3,3,3,0,0,0,0,0
3,0,0,0,3,0,0,0,0,0
3,0,0,0,3,0,0,0,0,0
3,0,0,0,3,0,0,0,0,0
0,0,0,0,3,0,0,0,0,0
3,0,0,0,3,0,0,0,0,0
3,0,0,0,3,0,0,0,0,0
3,0,0,0,3,0,0,0,0,0
3,3,3,3,3,0,0,0,0,0
endlayer

