# Converted from schematic
# THIS TEMPLATE USES DEFAULTS!  Please edit for corrections.
# If you need help, consult template_rules.txt

weight=1
embed_into_distance=1
acceptable_target_blocks=1,2,3,12,13
dimensions=7,11,10
allowable_overhang=0
max_cut_in=2
cut_in_buffer=1
max_leveling=2
leveling_buffer=1
preserve_water=0
preserve_lava=0
preserve_plants=0


rule1=0,100,12
rule2=0,100,24
rule3=0,100,64-1
rule4=0,100,64-8
rule5=0,100,101
rule6=0,100,50-1
rule7=0,100,50-4
rule8=0,100,44-1


layer
2,2,2,2,2,1,1,1,1,1
2,2,2,2,2,2,2,2,2,1
2,2,2,2,2,2,2,2,2,1
2,2,2,2,2,2,2,2,2,1
2,2,2,2,2,1,1,1,1,1
2,2,2,2,2,1,1,1,1,1
2,2,2,2,2,1,1,1,1,1
2,2,2,2,2,1,1,1,1,1
2,2,2,2,2,1,1,1,1,1
2,2,2,2,2,1,1,1,1,1
2,2,2,2,2,1,1,1,1,1
endlayer

layer
2,2,2,2,2,2,2,2,2,0
2,0,0,0,0,0,0,0,2,0
2,0,0,0,0,0,0,0,3,0
2,0,0,0,0,0,0,0,2,0
2,0,0,0,2,2,2,2,2,0
2,0,0,0,2,0,0,0,0,0
2,0,0,0,2,0,0,0,0,0
2,0,0,0,2,0,0,0,0,0
2,0,0,0,2,0,0,0,0,0
2,0,0,0,2,0,0,0,0,0
2,2,2,2,2,0,0,0,0,0
endlayer

layer
2,2,2,2,2,2,2,2,2,0
2,0,0,0,0,0,0,0,2,0
5,0,0,0,0,0,0,0,4,0
5,0,0,0,0,0,0,0,2,0
2,0,0,0,2,2,2,2,2,0
2,0,0,0,2,0,0,0,0,0
2,0,0,0,2,0,0,0,0,0
5,0,0,0,2,0,0,0,0,0
5,0,0,0,2,0,0,0,0,0
2,0,0,0,2,0,0,0,0,0
2,2,2,2,2,0,0,0,0,0
endlayer

layer
2,2,5,2,2,2,2,5,2,0
2,0,0,0,0,6,0,0,2,0
2,0,0,0,0,0,0,0,2,0
2,7,0,0,0,0,0,0,2,0
2,0,0,0,2,2,2,5,2,0
2,0,0,0,2,0,0,0,0,0
2,0,0,0,2,0,0,0,0,0
2,0,0,0,2,0,0,0,0,0
2,0,0,0,5,0,0,0,0,0
2,0,0,0,2,0,0,0,0,0
2,2,2,2,2,0,0,0,0,0
endlayer

layer
2,2,2,2,2,2,2,2,2,0
2,7,0,0,0,0,0,0,2,8
2,0,0,0,0,0,0,0,2,8
2,0,0,0,0,0,0,0,2,8
2,0,0,0,2,2,2,2,2,0
2,0,0,0,2,0,0,0,0,0
2,0,0,0,2,0,0,0,0,0
2,0,0,0,2,0,0,0,0,0
2,0,0,0,2,0,0,0,0,0
2,0,0,0,2,0,0,0,0,0
2,2,2,2,2,0,0,0,0,0
endlayer

layer
2,2,2,2,2,2,2,2,2,0
2,2,2,2,2,2,2,2,2,0
2,2,2,2,2,2,2,2,2,0
2,2,2,2,2,2,2,2,2,0
2,2,2,2,2,2,2,2,2,0
2,2,2,2,2,0,0,0,0,0
2,2,2,2,2,0,0,0,0,0
2,2,2,2,2,0,0,0,0,0
2,2,2,2,2,0,0,0,0,0
2,2,2,2,2,0,0,0,0,0
2,2,2,2,2,0,0,0,0,0
endlayer

layer
8,8,8,8,8,8,8,8,8,0
8,0,0,0,0,0,0,0,8,0
8,0,0,0,0,0,0,0,8,0
8,0,0,0,0,0,0,0,8,0
8,0,0,0,8,8,8,8,8,0
8,0,0,0,8,0,0,0,0,0
8,0,0,0,8,0,0,0,0,0
8,0,0,0,8,0,0,0,0,0
8,0,0,0,8,0,0,0,0,0
8,0,0,0,8,0,0,0,0,0
8,8,8,8,8,0,0,0,0,0
endlayer

