# Converted from schematic
# THIS TEMPLATE USES DEFAULTS!  Please edit for corrections.
# If you need help, consult template_rules.txt

weight=2
embed_into_distance=1
acceptable_target_blocks=1,2,3,12,13,24
dimensions=38,7,7
allowable_overhang=0
max_cut_in=38
cut_in_buffer=0
max_leveling=0
leveling_buffer=0
preserve_water=0
preserve_lava=0
preserve_plants=1


rule1=0,100,98-1
rule2=0,100,98,98,98,98,98-1
rule3=0,100,1
rule4=0,100,50-5
rule5=0,100,109-6
rule6=0,100,109-4
rule7=0,100,109-5
rule8=0,100,109-7


layer
0,0,0,0,0,0,0
0,2,1,1,2,1,0
0,2,3,3,3,2,0
0,2,3,3,3,1,0
0,2,3,3,3,1,0
0,2,2,2,2,1,0
0,0,0,0,0,0,0
endlayer

layer
0,0,0,0,0,0,0
0,2,0,0,0,2,0
0,2,0,0,0,2,0
0,2,0,0,0,2,0
0,2,4,0,0,2,0
0,2,2,2,2,1,0
0,0,0,0,0,0,0
endlayer

layer
0,0,0,0,0,0,0
0,2,0,0,0,2,0
0,2,0,0,0,2,0
0,2,0,0,0,2,0
0,2,0,0,0,2,0
0,2,2,2,2,2,0
0,0,0,0,0,0,0
endlayer

layer
0,0,0,0,0,0,0
0,2,0,0,0,2,0
0,2,0,0,0,2,0
0,2,0,0,0,2,0
0,2,0,0,0,2,0
0,2,2,2,2,2,0
0,0,0,0,0,0,0
endlayer

layer
0,0,0,0,0,0,0
0,2,2,2,2,2,0
0,2,0,0,0,2,0
0,2,0,0,0,2,0
0,2,0,0,0,2,0
0,2,2,2,2,2,0
0,0,0,0,0,0,0
endlayer

layer
0,0,0,0,0,0,0
0,2,2,2,2,2,0
0,2,0,0,0,2,0
0,0,0,0,0,2,0
0,2,0,0,0,2,0
0,2,2,2,2,2,0
0,0,0,0,0,0,0
endlayer

layer
0,0,0,0,0,0,0
0,2,2,2,2,2,0
0,2,0,0,0,2,0
0,0,0,0,0,2,0
0,2,0,0,0,2,0
0,2,2,2,2,2,0
0,0,0,0,0,0,0
endlayer

layer
0,0,0,0,0,0,0
0,2,2,2,2,2,0
0,2,0,0,0,2,0
0,2,0,0,0,2,0
0,2,0,0,0,2,0
0,2,2,2,2,2,0
0,0,0,0,0,0,0
endlayer

layer
0,0,0,0,0,0,0
0,2,2,2,2,2,0
0,2,3,3,3,2,0
0,2,3,3,3,2,0
0,2,3,0,3,2,0
0,2,2,2,2,2,0
0,0,0,0,0,0,0
endlayer

layer
0,0,0,0,0,0,0
0,2,2,0,2,2,0
0,2,0,0,0,2,0
0,2,0,0,0,2,0
0,2,4,0,0,2,0
0,2,2,2,2,2,0
0,0,0,0,0,0,0
endlayer

layer
0,0,0,0,0,0,0
0,2,2,0,2,2,0
0,2,0,0,0,2,0
0,2,0,0,0,2,0
0,2,0,0,0,2,0
0,2,2,2,2,2,0
0,0,0,0,0,0,0
endlayer

layer
0,0,0,0,0,0,0
0,2,2,2,2,2,0
0,2,0,0,0,2,0
0,0,0,0,0,2,0
0,2,0,0,0,2,0
0,2,2,2,2,2,0
0,0,0,0,0,0,0
endlayer

layer
0,0,0,0,0,0,0
0,2,2,2,2,2,0
0,2,0,0,0,2,0
0,0,0,0,0,2,0
0,2,0,0,0,2,0
0,2,2,2,2,2,0
0,0,0,0,0,0,0
endlayer

layer
0,0,0,0,0,0,0
0,2,2,2,2,2,0
0,2,0,0,0,2,0
0,2,0,0,0,2,0
0,2,0,0,0,2,0
0,2,2,2,2,2,0
0,0,0,0,0,0,0
endlayer

layer
0,0,0,0,0,0,0
0,2,2,2,2,2,0
0,2,0,0,0,2,0
0,2,0,0,0,2,0
0,2,0,0,0,2,0
0,2,2,2,2,2,0
0,0,0,0,0,0,0
endlayer

layer
0,0,0,0,0,0,0
0,2,2,2,2,2,0
0,2,3,3,3,2,0
0,2,3,3,3,2,0
0,2,3,0,3,2,0
0,2,2,2,2,2,0
0,0,0,0,0,0,0
endlayer

layer
0,0,0,0,0,0,0
0,2,2,0,2,2,0
0,2,0,0,0,2,0
0,2,0,0,0,2,0
0,2,4,0,0,2,0
0,2,2,2,2,2,0
0,0,0,0,0,0,0
endlayer

layer
0,0,0,0,0,0,0
0,2,2,0,2,2,0
0,2,0,0,0,2,0
0,2,0,0,0,2,0
0,2,0,0,0,2,0
0,2,2,2,2,2,0
0,0,0,0,0,0,0
endlayer

layer
0,0,0,0,0,0,0
0,2,2,2,2,2,0
0,2,0,0,0,2,0
0,0,0,0,0,2,0
0,2,0,0,0,2,0
0,2,2,2,2,2,0
0,0,0,0,0,0,0
endlayer

layer
0,0,0,0,0,0,0
0,2,2,2,2,2,0
0,2,0,0,0,2,0
0,0,0,0,0,2,0
0,2,0,0,0,2,0
0,2,2,2,2,2,0
0,0,0,0,0,0,0
endlayer

layer
0,0,0,0,0,0,0
0,2,2,2,2,2,0
0,2,0,0,0,2,0
0,2,0,0,0,2,0
0,2,0,0,0,2,0
0,2,2,2,2,2,0
0,0,0,0,0,0,0
endlayer

layer
0,0,0,0,0,0,0
0,2,2,2,2,2,0
0,2,0,0,0,2,0
0,2,0,0,0,2,0
0,2,0,0,0,2,0
0,2,2,2,2,2,0
0,0,0,0,0,0,0
endlayer

layer
0,0,0,0,0,0,0
0,2,2,2,2,2,0
0,2,3,3,3,2,0
0,2,3,3,3,2,0
0,2,3,0,3,2,0
0,2,2,2,2,2,0
0,0,0,0,0,0,0
endlayer

layer
0,0,0,0,0,0,0
0,2,2,0,2,2,0
0,2,0,0,0,2,0
0,2,0,0,0,2,0
0,2,4,0,0,2,0
0,2,2,2,2,2,0
0,0,0,0,0,0,0
endlayer

layer
0,0,0,0,0,0,0
0,2,2,0,2,2,0
0,2,0,0,0,2,0
0,2,0,0,0,2,0
0,2,0,0,0,2,0
0,2,2,2,2,2,0
0,0,0,0,0,0,0
endlayer

layer
0,0,0,0,0,0,0
0,2,2,2,2,2,0
0,2,0,0,0,2,0
0,0,0,0,0,2,0
0,2,0,0,0,2,0
0,2,2,2,2,2,0
0,0,0,0,0,0,0
endlayer

layer
0,0,0,0,0,0,0
0,2,2,2,2,2,0
0,2,0,0,0,2,0
0,0,0,0,0,2,0
0,2,0,0,0,2,0
0,2,2,2,2,2,0
0,0,0,0,0,0,0
endlayer

layer
0,0,0,0,0,0,0
0,2,2,2,2,2,0
0,2,0,0,0,2,0
0,2,0,0,0,2,0
0,2,0,0,0,2,0
0,2,2,2,2,2,0
0,0,0,0,0,0,0
endlayer

layer
0,0,0,0,0,0,0
0,2,2,2,2,2,0
0,2,0,0,0,2,0
0,2,0,0,0,2,0
0,2,0,0,0,2,0
0,2,2,2,2,2,0
0,0,0,0,0,0,0
endlayer

layer
0,0,0,0,0,0,0
0,2,2,2,2,2,0
0,2,0,0,0,2,0
0,2,0,0,0,2,0
0,2,0,0,0,2,0
0,2,2,0,2,2,0
0,0,0,0,0,0,0
endlayer

layer
0,0,0,0,0,0,0
0,2,2,4,2,2,0
0,2,0,0,0,2,0
0,2,0,0,0,2,0
0,2,0,0,0,2,0
0,2,2,0,2,2,0
0,0,0,0,0,0,0
endlayer

layer
0,0,0,0,0,0,0
0,2,2,0,2,2,0
0,2,0,0,0,2,0
0,2,0,0,0,2,0
0,2,0,0,0,2,0
0,2,2,2,2,2,0
0,0,0,0,0,0,0
endlayer

layer
0,0,0,0,0,0,0
0,3,3,3,3,3,0
0,3,0,0,0,3,0
0,3,0,0,0,3,0
0,3,0,0,0,3,0
0,3,3,3,3,3,0
0,0,0,0,0,0,0
endlayer

layer
0,0,0,0,0,0,0
0,2,2,2,2,2,0
0,2,0,0,0,2,0
0,2,0,0,0,2,0
0,2,0,0,0,2,0
0,2,2,2,2,2,0
0,0,0,0,0,0,0
endlayer

layer
8,6,6,6,6,6,5
8,2,2,2,2,2,5
8,2,0,0,0,2,5
8,2,0,0,0,2,5
8,2,0,0,0,2,5
8,2,2,2,2,2,5
8,7,7,7,7,7,5
endlayer

layer
2,2,2,2,2,2,2
2,2,2,2,2,2,2
2,2,3,3,3,2,2
2,2,3,3,3,2,2
2,2,3,0,3,2,2
2,2,2,2,2,2,2
2,2,2,2,2,2,2
endlayer

layer
2,2,2,2,2,2,2
2,4,0,0,0,4,2
2,0,0,0,0,0,2
2,0,0,0,0,0,2
2,0,0,0,0,0,2
2,4,0,0,0,4,2
2,2,2,2,2,2,2
endlayer

layer
2,0,2,0,2,0,2
0,0,0,0,0,0,0
2,0,0,0,0,0,2
0,0,0,0,0,0,0
2,0,0,0,0,0,2
0,0,0,0,0,0,0
2,0,2,0,2,0,2
endlayer

