# Converted from schematic
# THIS TEMPLATE USES DEFAULTS!  Please edit for corrections.
# If you need help, consult template_rules.txt

weight=1
embed_into_distance=1
acceptable_target_blocks=1,2,3,12,13,24
dimensions=27,9,9
allowable_overhang=0
max_cut_in=27
cut_in_buffer=0
max_leveling=0
leveling_buffer=0
preserve_water=0
preserve_lava=0
preserve_plants=1


rule1=0,100,1
rule2=0,100,98
rule3=0,100,159-14
rule4=0,100,109-3
rule5=0,100,65-3
rule6=0,100,54-3
rule7=0,100,102
rule8=0,100,109-5
rule9=0,100,109-4
rule10=0,100,65-4
rule11=0,100,109-2
rule12=0,100,109
rule13=0,100,20
rule14=0,100,44-2
rule15=0,100,109-1


layer
0,0,0,0,0,0,0,0,0
0,1,1,1,1,1,1,1,0
0,1,1,1,1,1,1,1,0
0,1,1,1,1,1,1,1,0
0,1,1,1,1,1,1,1,0
0,1,1,1,1,1,1,1,0
0,1,1,1,1,1,1,1,0
0,2,1,1,1,1,1,2,0
0,0,0,0,0,0,0,0,0
endlayer

layer
0,0,0,0,0,0,0,0,0
0,2,1,1,1,1,1,2,0
0,1,2,2,2,2,2,1,0
0,0,4,2,3,3,2,1,0
0,0,4,2,3,3,2,1,0
0,0,4,2,3,3,2,1,0
0,1,2,2,2,2,2,1,0
0,2,1,1,1,1,1,2,0
0,0,0,0,0,0,0,0,0
endlayer

layer
0,0,0,0,0,0,0,0,0
0,2,1,1,1,1,1,2,0
0,1,2,0,0,4,2,1,0
0,0,0,0,0,0,2,1,0
0,0,0,0,0,5,1,1,0
0,0,0,0,0,0,2,1,0
0,1,2,0,0,4,2,1,0
0,2,1,1,1,1,1,2,0
0,0,0,0,0,0,0,0,0
endlayer

layer
0,0,0,0,0,0,0,0,0
0,2,1,1,7,1,1,2,0
0,1,2,0,0,0,6,1,0
0,0,0,0,0,0,0,1,0
0,0,0,0,0,5,1,1,0
0,0,0,0,0,0,0,1,0
0,1,2,0,0,0,0,1,0
0,2,1,1,7,1,1,2,0
0,0,0,0,0,0,0,0,0
endlayer

layer
0,0,0,0,0,0,0,0,0
0,2,1,1,7,1,1,2,0
0,1,2,0,0,0,0,1,0
0,8,8,0,0,0,0,1,0
0,0,0,0,0,5,1,1,0
0,9,9,0,0,0,0,1,0
0,1,2,0,0,0,0,1,0
0,2,1,1,7,1,1,2,0
0,0,0,0,0,0,0,0,0
endlayer

layer
0,0,0,0,0,0,0,0,0
0,2,1,1,1,1,1,2,0
0,1,2,0,0,0,0,1,0
0,1,1,0,0,0,0,1,0
0,1,2,0,0,5,1,1,0
0,1,1,0,0,0,0,1,0
0,1,2,0,0,0,0,1,0
0,2,1,1,1,1,1,2,0
0,0,0,0,0,0,0,0,0
endlayer

layer
0,0,0,0,0,0,0,0,0
0,2,1,1,1,1,1,2,0
0,1,0,0,0,0,0,1,0
0,1,1,0,0,0,0,1,0
0,1,1,0,0,5,1,1,0
0,1,1,0,0,0,0,1,0
0,1,0,0,0,0,0,1,0
0,2,1,1,1,1,1,2,0
0,0,0,0,0,0,0,0,0
endlayer

layer
0,0,0,0,0,0,0,0,0
0,2,1,1,1,1,1,2,0
0,1,0,0,0,0,0,1,0
0,1,0,0,0,0,0,1,0
0,1,0,0,0,5,1,1,0
0,1,0,0,0,0,0,1,0
0,1,0,0,0,0,0,1,0
0,2,1,1,1,1,1,2,0
0,0,0,0,0,0,0,0,0
endlayer

layer
0,0,0,0,0,0,0,0,0
0,2,1,1,1,1,1,2,0
0,1,0,0,0,0,0,1,0
0,1,0,0,0,0,0,1,0
0,1,0,0,0,5,1,1,0
0,1,0,0,0,0,0,1,0
0,1,0,0,0,0,0,1,0
0,2,1,1,1,1,1,2,0
0,0,0,0,0,0,0,0,0
endlayer

layer
0,0,0,0,0,0,0,0,0
0,2,1,1,1,1,1,2,0
0,1,2,2,2,2,2,1,0
0,1,2,2,2,2,2,1,0
0,1,2,2,0,5,2,1,0
0,1,2,2,2,2,2,1,0
0,1,2,2,2,2,2,1,0
0,2,1,1,1,1,1,2,0
0,0,0,0,0,0,0,0,0
endlayer

layer
0,0,0,0,0,0,0,0,0
0,2,2,2,2,2,2,2,0
0,2,2,1,1,1,2,2,0
0,2,1,0,0,0,1,2,0
0,2,1,0,0,0,1,2,0
0,2,1,0,0,10,1,2,0
0,2,2,1,1,1,2,2,0
0,2,2,2,2,2,2,2,0
0,0,0,0,0,0,0,0,0
endlayer

layer
0,0,0,0,0,0,0,0,0
0,0,2,0,0,0,2,0,0
0,2,2,1,7,1,2,2,0
0,0,1,0,0,0,1,0,0
0,0,7,0,0,0,7,0,0
0,0,1,0,0,10,1,0,0
0,2,2,1,7,1,2,2,0
0,0,2,0,0,0,2,0,0
0,0,0,0,0,0,0,0,0
endlayer

layer
0,0,0,0,0,0,0,0,0
0,0,2,0,0,0,2,0,0
0,2,2,1,1,1,2,2,0
0,0,1,0,0,0,1,0,0
0,0,1,0,0,0,1,0,0
0,0,1,0,0,10,1,0,0
0,2,2,1,1,1,2,2,0
0,0,2,0,0,0,2,0,0
0,0,0,0,0,0,0,0,0
endlayer

layer
0,0,0,0,0,0,0,0,0
0,0,2,0,0,0,2,0,0
0,2,2,1,1,1,2,2,0
0,0,1,0,0,0,1,0,0
0,0,1,0,0,0,1,0,0
0,0,1,0,0,10,1,0,0
0,2,2,1,1,1,2,2,0
0,0,2,0,0,0,2,0,0
0,0,0,0,0,0,0,0,0
endlayer

layer
0,0,0,0,0,0,0,0,0
0,2,2,2,2,2,2,2,0
0,2,2,2,2,2,2,2,0
0,2,2,0,0,0,2,2,0
0,2,2,0,0,0,2,2,0
0,2,2,0,0,10,2,2,0
0,2,2,2,2,2,2,2,0
0,2,2,2,2,2,2,2,0
0,0,0,0,0,0,0,0,0
endlayer

layer
0,0,0,0,0,0,0,0,0
0,2,1,1,1,1,1,2,0
0,1,0,2,11,0,0,1,0
0,1,0,0,0,0,0,1,0
0,1,0,0,0,0,0,1,0
0,1,0,0,0,0,0,1,0
0,1,0,0,0,0,0,1,0
0,2,1,1,1,1,1,2,0
0,0,0,0,0,0,0,0,0
endlayer

layer
0,0,0,0,0,0,0,0,0
0,2,1,1,1,1,1,2,0
0,1,2,11,0,0,0,1,0
0,1,2,0,0,0,0,1,0
0,1,0,0,0,0,0,1,0
0,1,0,0,0,0,0,1,0
0,1,0,0,0,0,0,1,0
0,2,1,1,1,1,1,2,0
0,0,0,0,0,0,0,0,0
endlayer

layer
0,0,0,0,0,0,0,0,0
0,2,1,1,7,1,1,2,0
0,1,0,0,0,0,0,1,0
0,1,12,0,0,0,0,1,0
0,7,2,0,0,0,0,7,0
0,1,0,0,0,0,0,1,0
0,1,0,0,0,0,0,1,0
0,2,1,1,7,1,1,2,0
0,0,0,0,0,0,0,0,0
endlayer

layer
0,0,0,0,0,0,0,0,0
0,2,1,1,7,1,1,2,0
0,1,0,0,0,0,0,1,0
0,1,0,0,0,0,0,1,0
0,7,12,0,0,0,0,7,0
0,1,2,0,0,0,0,1,0
0,1,0,0,0,0,0,1,0
0,2,1,1,7,1,1,2,0
0,0,0,0,0,0,0,0,0
endlayer

layer
0,0,0,0,0,0,0,0,0
0,2,1,1,7,1,1,2,0
0,1,0,0,0,0,0,1,0
0,1,0,0,0,0,0,1,0
0,7,0,0,0,0,0,7,0
0,1,12,0,0,0,0,1,0
0,1,2,0,0,0,0,1,0
0,2,1,1,7,1,1,2,0
0,0,0,0,0,0,0,0,0
endlayer

layer
0,2,0,0,0,0,0,2,0
2,2,1,1,1,1,1,2,2
0,1,1,1,1,1,1,1,0
0,1,0,1,1,1,1,1,0
0,1,0,1,13,1,1,1,0
0,1,0,1,1,1,1,1,0
0,1,0,4,1,1,1,1,0
2,2,1,1,1,1,1,2,2
0,2,0,0,0,0,0,2,0
endlayer

layer
0,2,0,0,0,0,0,2,0
2,2,2,2,2,2,2,2,2
0,2,0,0,0,0,0,2,0
0,2,0,0,0,0,0,2,0
0,2,0,0,0,0,0,2,0
0,2,0,0,0,0,0,2,0
0,2,0,0,4,2,2,2,0
2,2,2,2,2,2,2,2,2
0,2,0,0,0,0,0,2,0
endlayer

layer
2,2,2,2,2,2,2,2,2
2,0,0,0,0,0,0,0,2
2,0,0,0,0,0,0,0,2
2,0,0,0,0,0,0,0,2
2,0,0,0,0,0,0,0,2
2,0,0,0,0,0,0,0,2
2,0,0,0,0,4,1,1,2
2,0,0,0,0,0,0,0,2
2,2,2,2,2,2,2,2,2
endlayer

layer
2,1,1,1,1,1,1,1,2
1,0,0,0,0,0,0,0,1
1,0,0,0,0,0,0,0,1
1,0,0,0,0,0,0,0,1
1,0,0,0,0,0,0,0,1
1,0,0,0,0,0,0,0,1
1,0,0,0,0,0,4,1,1
1,0,0,0,0,0,0,0,1
2,1,1,1,1,1,1,1,2
endlayer

layer
2,1,2,2,2,2,2,1,2
1,14,14,14,14,14,14,14,1
2,14,0,0,0,0,0,14,2
2,14,0,0,0,0,0,14,2
2,14,0,0,0,0,0,14,2
2,14,0,0,0,0,0,14,2
2,14,0,0,0,0,0,14,2
1,14,14,14,14,14,14,14,1
2,1,2,2,2,2,2,1,2
endlayer

layer
2,2,2,0,15,0,2,2,2
2,0,0,0,0,0,0,0,2
2,0,0,0,0,0,0,0,2
0,0,0,0,0,0,0,0,0
11,0,0,0,0,0,0,0,4
0,0,0,0,0,0,0,0,0
2,0,0,0,0,0,0,0,2
2,0,0,0,0,0,0,0,2
2,2,2,0,12,0,2,2,2
endlayer

layer
2,0,2,0,0,0,2,0,2
0,0,0,0,0,0,0,0,0
2,0,0,0,0,0,0,0,2
0,0,0,0,0,0,0,0,0
0,0,0,0,0,0,0,0,0
0,0,0,0,0,0,0,0,0
2,0,0,0,0,0,0,0,2
0,0,0,0,0,0,0,0,0
2,0,2,0,0,0,2,0,2
endlayer

