{
    "registryname": "pizzaoven",
    "localizedname": "Pizza Oven",
    "requires-blueprint": false,
    "parts": [
        {
            "x": -2,
            "y": 0,
            "z": 2,
            "elements": "brickBlocks"
        },
        {
            "x": -1,
            "y": 2,
            "z": 3,
            "elements": "brickBlocks"
        },
        {
            "x": -1,
            "y": 0,
            "z": 0,
            "elements": "brickBlocks"
        },
        {
            "x": 1,
            "y": 2,
            "z": 1,
            "elements": "brickBlocks"
        },
        {
            "x": 0,
            "y": 2,
            "z": 3,
            "elements": "brickBlocks"
        },
        {
            "x": 1,
            "y": 0,
            "z": 0,
            "elements": "brickBlocks"
        },
        {
            "x": -1,
            "y": 0,
            "z": 2,
            "elements": "netherrack"
        },
        {
            "x": 0,
            "y": 0,
            "z": 2,
            "elements": "netherrack"
        },
        {
            "x": 1,
            "y": 2,
            "z": 3,
            "elements": "brickBlocks"
        },
        {
            "x": 1,
            "y": 0,
            "z": 2,
            "elements": "netherrack"
        },
        {
            "x": -1,
            "y": 0,
            "z": 4,
            "elements": "brickBlocks"
        },
        {
            "x": 2,
            "y": 0,
            "z": 2,
            "elements": "brickBlocks"
        },
        {
            "x": 0,
            "y": 0,
            "z": 4,
            "elements": [
                "modularmachinery:blockinputbus@1"
            ]
        },
        {
            "x": 1,
            "y": 0,
            "z": 4,
            "elements": "brickBlocks"
        },
        {
            "x": -1,
            "y": 1,
            "z": 0,
            "elements": "brickBlocks"
        },
        {
            "x": 0,
            "y": 1,
            "z": 0,
            "elements": "brickBlocks"
        },
        {
            "x": -2,
            "y": 1,
            "z": 2,
            "elements": "brickBlocks"
        },
        {
            "x": -1,
            "y": 1,
            "z": 2,
            "elements": [
                "minecraft:fire"
            ]
        },
        {
            "x": 1,
            "y": 1,
            "z": 0,
            "elements": "brickBlocks"
        },
        {
            "x": 0,
            "y": 1,
            "z": 2,
            "elements": [
                "minecraft:fire"
            ]
        },
        {
            "x": -1,
            "y": -1,
            "z": 1,
            "elements": "brickBlocks"
        },
        {
            "x": 0,
            "y": -1,
            "z": 1,
            "elements": "brickBlocks"
        },
        {
            "x": -1,
            "y": 1,
            "z": 4,
            "elements": "brickBlocks"
        },
        {
            "x": 1,
            "y": 1,
            "z": 2,
            "elements": [
                "minecraft:fire"
            ]
        },
        {
            "x": 0,
            "y": 1,
            "z": 4,
            "elements": "bars"
        },
        {
            "x": 2,
            "y": 1,
            "z": 2,
            "elements": "brickBlocks"
        },
        {
            "x": 1,
            "y": -1,
            "z": 1,
            "elements": "brickBlocks"
        },
        {
            "x": -1,
            "y": -1,
            "z": 3,
            "elements": "brickBlocks"
        },
        {
            "x": 0,
            "y": -1,
            "z": 3,
            "elements": "brickBlocks"
        },
        {
            "x": 1,
            "y": 1,
            "z": 4,
            "elements": "brickBlocks"
        },
        {
            "x": 1,
            "y": -1,
            "z": 3,
            "elements": "brickBlocks"
        },
        {
            "x": -2,
            "y": 0,
            "z": 1,
            "elements": "brickBlocks"
        },
        {
            "x": -1,
            "y": 2,
            "z": 2,
            "elements": "brickBlocks"
        },
        {
            "x": 0,
            "y": 2,
            "z": 2,
            "elements": [
                "chutes:chute_wood"
            ]
        },
        {
            "x": -1,
            "y": 0,
            "z": 1,
            "elements": "netherrack"
        },
        {
            "x": 0,
            "y": 0,
            "z": 1,
            "elements": "netherrack"
        },
        {
            "x": -2,
            "y": 0,
            "z": 3,
            "elements": "brickBlocks"
        },
        {
            "x": 1,
            "y": 2,
            "z": 2,
            "elements": "brickBlocks"
        },
        {
            "x": 0,
            "y": 2,
            "z": 4,
            "elements": "brickBlocks"
        },
        {
            "x": 1,
            "y": 0,
            "z": 1,
            "elements": "netherrack"
        },
        {
            "x": -1,
            "y": 0,
            "z": 3,
            "elements": "netherrack"
        },
        {
            "x": 2,
            "y": 0,
            "z": 1,
            "elements": "brickBlocks"
        },
        {
            "x": 0,
            "y": 0,
            "z": 3,
            "elements": "netherrack"
        },
        {
            "x": 1,
            "y": 0,
            "z": 3,
            "elements": "netherrack"
        },
        {
            "x": 2,
            "y": 0,
            "z": 3,
            "elements": "brickBlocks"
        },
        {
            "x": -2,
            "y": 1,
            "z": 1,
            "elements": "brickBlocks"
        },
        {
            "x": -1,
            "y": 1,
            "z": 1,
            "elements": [
                "minecraft:fire"
            ]
        },
        {
            "x": 0,
            "y": 3,
            "z": 2,
            "elements": [
                "chutes:chute_wood"
            ]
        },
        {
            "x": 0,
            "y": 1,
            "z": 1,
            "elements": [
                "minecraft:fire"
            ]
        },
        {
            "x": -2,
            "y": 1,
            "z": 3,
            "elements": "brickBlocks"
        },
        {
            "x": -1,
            "y": 1,
            "z": 3,
            "elements": [
                "minecraft:fire"
            ]
        },
        {
            "x": 1,
            "y": 1,
            "z": 1,
            "elements": [
                "minecraft:fire"
            ]
        },
        {
            "x": 0,
            "y": 1,
            "z": 3,
            "elements": [
                "minecraft:fire"
            ]
        },
        {
            "x": 2,
            "y": 1,
            "z": 1,
            "elements": "brickBlocks"
        },
        {
            "x": -1,
            "y": -1,
            "z": 2,
            "elements": "brickBlocks"
        },
        {
            "x": 0,
            "y": -1,
            "z": 2,
            "elements": [
                "modularmachinery:blockoutputbus"
            ]
        },
        {
            "x": 1,
            "y": 1,
            "z": 3,
            "elements": [
                "minecraft:fire"
            ]
        },
        {
            "x": 2,
            "y": 1,
            "z": 3,
            "elements": "brickBlocks"
        },
        {
            "x": 1,
            "y": -1,
            "z": 2,
            "elements": "brickBlocks"
        },
        {
            "x": -1,
            "y": 2,
            "z": 1,
            "elements": "brickBlocks"
        },
        {
            "x": 0,
            "y": 2,
            "z": 1,
            "elements": "brickBlocks"
        }
    ]}